Wed Oct 28 17:37:24 BRST 2015 : Apache Derby Servidor de Rede - 10.10.2.0 - (1582446) iniciado e pronto para aceitar conexões na porta 1527 em {3}
----------------------------------------------------------------
Wed Oct 28 17:37:24 BRST 2015:
 Inicializando o Derby versão The Apache Software Foundation - Apache Derby - 10.10.2.0 - (1582446): instância a816c00e-0150-aff4-70d3-000076cdc0d5
no diretório de banco de dados E:\faculdade\terceiro semestre 2\Linguagem de Programação II\Lab\lab0-Projeto LP2\ProjetoLp2\BancoDeDados\projetoLP2_DB 

java.vendor=Oracle Corporation
java.runtime.version=1.8.0_40-b26
user.dir=C:\Program Files\GlassFish_Server\javadb
os.name=Windows 7
os.arch=amd64
os.version=6.1
derby.system.home=E:\faculdade\terceiro semestre 2\Linguagem de Programação II\Lab\lab0-Projeto LP2\ProjetoLp2\BancoDeDados
Carregador de classe do banco de dados iniciado - derby.database.classpath=''
Wed Oct 28 17:37:25 BRST 2015 Thread[DRDAConnThread_2,5,main] (XID = 9913), (SESSIONID = 0), (DATABASE = projetoLP2_DB), (DRDAID = {1}), Cleanup action starting
java.sql.SQLNonTransientConnectionException: Ocorreu uma falha de autenticação da conexão.  Motivo: Autenticação inválida..
	at org.apache.derby.impl.jdbc.SQLExceptionFactory40.getSQLException(Unknown Source)
	at org.apache.derby.impl.jdbc.Util.newEmbedSQLException(Unknown Source)
	at org.apache.derby.impl.jdbc.Util.newEmbedSQLException(Unknown Source)
	at org.apache.derby.impl.jdbc.Util.generateCsSQLException(Unknown Source)
	at org.apache.derby.impl.jdbc.EmbedConnection.newSQLException(Unknown Source)
	at org.apache.derby.impl.jdbc.EmbedConnection.checkUserCredentials(Unknown Source)
	at org.apache.derby.impl.jdbc.EmbedConnection.<init>(Unknown Source)
	at org.apache.derby.impl.jdbc.EmbedConnection40.<init>(Unknown Source)
	at org.apache.derby.jdbc.Driver40.getNewEmbedConnection(Unknown Source)
	at org.apache.derby.jdbc.InternalDriver.connect(Unknown Source)
	at org.apache.derby.jdbc.Driver20.connect(Unknown Source)
	at org.apache.derby.jdbc.EmbeddedDriver.connect(Unknown Source)
	at org.apache.derby.impl.drda.Database.makeConnection(Unknown Source)
	at org.apache.derby.impl.drda.DRDAConnThread.getConnFromDatabaseName(Unknown Source)
	at org.apache.derby.impl.drda.DRDAConnThread.verifyUserIdPassword(Unknown Source)
	at org.apache.derby.impl.drda.DRDAConnThread.parseSECCHK(Unknown Source)
	at org.apache.derby.impl.drda.DRDAConnThread.parseDRDAConnection(Unknown Source)
	at org.apache.derby.impl.drda.DRDAConnThread.processCommands(Unknown Source)
	at org.apache.derby.impl.drda.DRDAConnThread.run(Unknown Source)
Caused by: java.sql.SQLException: Ocorreu uma falha de autenticação da conexão.  Motivo: Autenticação inválida..
	at org.apache.derby.impl.jdbc.SQLExceptionFactory.getSQLException(Unknown Source)
	at org.apache.derby.impl.jdbc.SQLExceptionFactory40.wrapArgsForTransportAcrossDRDA(Unknown Source)
	... 19 more
============= begin nested exception, level (1) ===========
java.sql.SQLException: Ocorreu uma falha de autenticação da conexão.  Motivo: Autenticação inválida..
	at org.apache.derby.impl.jdbc.SQLExceptionFactory.getSQLException(Unknown Source)
	at org.apache.derby.impl.jdbc.SQLExceptionFactory40.wrapArgsForTransportAcrossDRDA(Unknown Source)
	at org.apache.derby.impl.jdbc.SQLExceptionFactory40.getSQLException(Unknown Source)
	at org.apache.derby.impl.jdbc.Util.newEmbedSQLException(Unknown Source)
	at org.apache.derby.impl.jdbc.Util.newEmbedSQLException(Unknown Source)
	at org.apache.derby.impl.jdbc.Util.generateCsSQLException(Unknown Source)
	at org.apache.derby.impl.jdbc.EmbedConnection.newSQLException(Unknown Source)
	at org.apache.derby.impl.jdbc.EmbedConnection.checkUserCredentials(Unknown Source)
	at org.apache.derby.impl.jdbc.EmbedConnection.<init>(Unknown Source)
	at org.apache.derby.impl.jdbc.EmbedConnection40.<init>(Unknown Source)
	at org.apache.derby.jdbc.Driver40.getNewEmbedConnection(Unknown Source)
	at org.apache.derby.jdbc.InternalDriver.connect(Unknown Source)
	at org.apache.derby.jdbc.Driver20.connect(Unknown Source)
	at org.apache.derby.jdbc.EmbeddedDriver.connect(Unknown Source)
	at org.apache.derby.impl.drda.Database.makeConnection(Unknown Source)
	at org.apache.derby.impl.drda.DRDAConnThread.getConnFromDatabaseName(Unknown Source)
	at org.apache.derby.impl.drda.DRDAConnThread.verifyUserIdPassword(Unknown Source)
	at org.apache.derby.impl.drda.DRDAConnThread.parseSECCHK(Unknown Source)
	at org.apache.derby.impl.drda.DRDAConnThread.parseDRDAConnection(Unknown Source)
	at org.apache.derby.impl.drda.DRDAConnThread.processCommands(Unknown Source)
	at org.apache.derby.impl.drda.DRDAConnThread.run(Unknown Source)
============= end nested exception, level (1) ===========
Cleanup action completed
Wed Oct 28 17:37:25 BRST 2015 Thread[DRDAConnThread_2,5,main] (DATABASE = projetoLP2_DB), (DRDAID = {1}), Ocorreu uma falha de autenticação da conexão.  Motivo: Autenticação inválida..
Wed Oct 28 18:30:06 BRST 2015 Thread[DRDAConnThread_4,5,main] Cleanup action starting
java.sql.SQLException: Banco de dados 'citacoesBD' não encontrado.
	at org.apache.derby.impl.jdbc.SQLExceptionFactory40.getSQLException(Unknown Source)
	at org.apache.derby.impl.jdbc.Util.newEmbedSQLException(Unknown Source)
	at org.apache.derby.impl.jdbc.Util.newEmbedSQLException(Unknown Source)
	at org.apache.derby.impl.jdbc.Util.generateCsSQLException(Unknown Source)
	at org.apache.derby.impl.jdbc.EmbedConnection.newSQLException(Unknown Source)
	at org.apache.derby.impl.jdbc.EmbedConnection.handleDBNotFound(Unknown Source)
	at org.apache.derby.impl.jdbc.EmbedConnection.<init>(Unknown Source)
	at org.apache.derby.impl.jdbc.EmbedConnection40.<init>(Unknown Source)
	at org.apache.derby.jdbc.Driver40.getNewEmbedConnection(Unknown Source)
	at org.apache.derby.jdbc.InternalDriver.connect(Unknown Source)
	at org.apache.derby.jdbc.Driver20.connect(Unknown Source)
	at org.apache.derby.jdbc.EmbeddedDriver.connect(Unknown Source)
	at org.apache.derby.impl.drda.Database.makeConnection(Unknown Source)
	at org.apache.derby.impl.drda.DRDAConnThread.getConnFromDatabaseName(Unknown Source)
	at org.apache.derby.impl.drda.DRDAConnThread.verifyUserIdPassword(Unknown Source)
	at org.apache.derby.impl.drda.DRDAConnThread.parseSECCHK(Unknown Source)
	at org.apache.derby.impl.drda.DRDAConnThread.parseDRDAConnection(Unknown Source)
	at org.apache.derby.impl.drda.DRDAConnThread.processCommands(Unknown Source)
	at org.apache.derby.impl.drda.DRDAConnThread.run(Unknown Source)
Caused by: java.sql.SQLException: Banco de dados 'citacoesBD' não encontrado.
	at org.apache.derby.impl.jdbc.SQLExceptionFactory.getSQLException(Unknown Source)
	at org.apache.derby.impl.jdbc.SQLExceptionFactory40.wrapArgsForTransportAcrossDRDA(Unknown Source)
	... 19 more
============= begin nested exception, level (1) ===========
java.sql.SQLException: Banco de dados 'citacoesBD' não encontrado.
	at org.apache.derby.impl.jdbc.SQLExceptionFactory.getSQLException(Unknown Source)
	at org.apache.derby.impl.jdbc.SQLExceptionFactory40.wrapArgsForTransportAcrossDRDA(Unknown Source)
	at org.apache.derby.impl.jdbc.SQLExceptionFactory40.getSQLException(Unknown Source)
	at org.apache.derby.impl.jdbc.Util.newEmbedSQLException(Unknown Source)
	at org.apache.derby.impl.jdbc.Util.newEmbedSQLException(Unknown Source)
	at org.apache.derby.impl.jdbc.Util.generateCsSQLException(Unknown Source)
	at org.apache.derby.impl.jdbc.EmbedConnection.newSQLException(Unknown Source)
	at org.apache.derby.impl.jdbc.EmbedConnection.handleDBNotFound(Unknown Source)
	at org.apache.derby.impl.jdbc.EmbedConnection.<init>(Unknown Source)
	at org.apache.derby.impl.jdbc.EmbedConnection40.<init>(Unknown Source)
	at org.apache.derby.jdbc.Driver40.getNewEmbedConnection(Unknown Source)
	at org.apache.derby.jdbc.InternalDriver.connect(Unknown Source)
	at org.apache.derby.jdbc.Driver20.connect(Unknown Source)
	at org.apache.derby.jdbc.EmbeddedDriver.connect(Unknown Source)
	at org.apache.derby.impl.drda.Database.makeConnection(Unknown Source)
	at org.apache.derby.impl.drda.DRDAConnThread.getConnFromDatabaseName(Unknown Source)
	at org.apache.derby.impl.drda.DRDAConnThread.verifyUserIdPassword(Unknown Source)
	at org.apache.derby.impl.drda.DRDAConnThread.parseSECCHK(Unknown Source)
	at org.apache.derby.impl.drda.DRDAConnThread.parseDRDAConnection(Unknown Source)
	at org.apache.derby.impl.drda.DRDAConnThread.processCommands(Unknown Source)
	at org.apache.derby.impl.drda.DRDAConnThread.run(Unknown Source)
============= end nested exception, level (1) ===========
Cleanup action completed
Wed Oct 28 18:30:06 BRST 2015 Thread[DRDAConnThread_4,5,main] (DATABASE = citacoesBD), (DRDAID = {4}), Banco de dados 'citacoesBD' não encontrado.
Wed Oct 28 18:30:17 BRST 2015 Thread[DRDAConnThread_4,5,main] Cleanup action starting
java.sql.SQLException: Banco de dados 'citacoesBD' não encontrado.
	at org.apache.derby.impl.jdbc.SQLExceptionFactory40.getSQLException(Unknown Source)
	at org.apache.derby.impl.jdbc.Util.newEmbedSQLException(Unknown Source)
	at org.apache.derby.impl.jdbc.Util.newEmbedSQLException(Unknown Source)
	at org.apache.derby.impl.jdbc.Util.generateCsSQLException(Unknown Source)
	at org.apache.derby.impl.jdbc.EmbedConnection.newSQLException(Unknown Source)
	at org.apache.derby.impl.jdbc.EmbedConnection.handleDBNotFound(Unknown Source)
	at org.apache.derby.impl.jdbc.EmbedConnection.<init>(Unknown Source)
	at org.apache.derby.impl.jdbc.EmbedConnection40.<init>(Unknown Source)
	at org.apache.derby.jdbc.Driver40.getNewEmbedConnection(Unknown Source)
	at org.apache.derby.jdbc.InternalDriver.connect(Unknown Source)
	at org.apache.derby.jdbc.Driver20.connect(Unknown Source)
	at org.apache.derby.jdbc.EmbeddedDriver.connect(Unknown Source)
	at org.apache.derby.impl.drda.Database.makeConnection(Unknown Source)
	at org.apache.derby.impl.drda.DRDAConnThread.getConnFromDatabaseName(Unknown Source)
	at org.apache.derby.impl.drda.DRDAConnThread.verifyUserIdPassword(Unknown Source)
	at org.apache.derby.impl.drda.DRDAConnThread.parseSECCHK(Unknown Source)
	at org.apache.derby.impl.drda.DRDAConnThread.parseDRDAConnection(Unknown Source)
	at org.apache.derby.impl.drda.DRDAConnThread.processCommands(Unknown Source)
	at org.apache.derby.impl.drda.DRDAConnThread.run(Unknown Source)
Caused by: java.sql.SQLException: Banco de dados 'citacoesBD' não encontrado.
	at org.apache.derby.impl.jdbc.SQLExceptionFactory.getSQLException(Unknown Source)
	at org.apache.derby.impl.jdbc.SQLExceptionFactory40.wrapArgsForTransportAcrossDRDA(Unknown Source)
	... 19 more
============= begin nested exception, level (1) ===========
java.sql.SQLException: Banco de dados 'citacoesBD' não encontrado.
	at org.apache.derby.impl.jdbc.SQLExceptionFactory.getSQLException(Unknown Source)
	at org.apache.derby.impl.jdbc.SQLExceptionFactory40.wrapArgsForTransportAcrossDRDA(Unknown Source)
	at org.apache.derby.impl.jdbc.SQLExceptionFactory40.getSQLException(Unknown Source)
	at org.apache.derby.impl.jdbc.Util.newEmbedSQLException(Unknown Source)
	at org.apache.derby.impl.jdbc.Util.newEmbedSQLException(Unknown Source)
	at org.apache.derby.impl.jdbc.Util.generateCsSQLException(Unknown Source)
	at org.apache.derby.impl.jdbc.EmbedConnection.newSQLException(Unknown Source)
	at org.apache.derby.impl.jdbc.EmbedConnection.handleDBNotFound(Unknown Source)
	at org.apache.derby.impl.jdbc.EmbedConnection.<init>(Unknown Source)
	at org.apache.derby.impl.jdbc.EmbedConnection40.<init>(Unknown Source)
	at org.apache.derby.jdbc.Driver40.getNewEmbedConnection(Unknown Source)
	at org.apache.derby.jdbc.InternalDriver.connect(Unknown Source)
	at org.apache.derby.jdbc.Driver20.connect(Unknown Source)
	at org.apache.derby.jdbc.EmbeddedDriver.connect(Unknown Source)
	at org.apache.derby.impl.drda.Database.makeConnection(Unknown Source)
	at org.apache.derby.impl.drda.DRDAConnThread.getConnFromDatabaseName(Unknown Source)
	at org.apache.derby.impl.drda.DRDAConnThread.verifyUserIdPassword(Unknown Source)
	at org.apache.derby.impl.drda.DRDAConnThread.parseSECCHK(Unknown Source)
	at org.apache.derby.impl.drda.DRDAConnThread.parseDRDAConnection(Unknown Source)
	at org.apache.derby.impl.drda.DRDAConnThread.processCommands(Unknown Source)
	at org.apache.derby.impl.drda.DRDAConnThread.run(Unknown Source)
============= end nested exception, level (1) ===========
Cleanup action completed
Wed Oct 28 18:30:17 BRST 2015 Thread[DRDAConnThread_4,5,main] (DATABASE = citacoesBD), (DRDAID = {5}), Banco de dados 'citacoesBD' não encontrado.
Wed Oct 28 18:39:27 BRST 2015 Thread[DRDAConnThread_4,5,main] Cleanup action starting
java.sql.SQLException: Banco de dados 'cinemaDB' não encontrado.
	at org.apache.derby.impl.jdbc.SQLExceptionFactory40.getSQLException(Unknown Source)
	at org.apache.derby.impl.jdbc.Util.newEmbedSQLException(Unknown Source)
	at org.apache.derby.impl.jdbc.Util.newEmbedSQLException(Unknown Source)
	at org.apache.derby.impl.jdbc.Util.generateCsSQLException(Unknown Source)
	at org.apache.derby.impl.jdbc.EmbedConnection.newSQLException(Unknown Source)
	at org.apache.derby.impl.jdbc.EmbedConnection.handleDBNotFound(Unknown Source)
	at org.apache.derby.impl.jdbc.EmbedConnection.<init>(Unknown Source)
	at org.apache.derby.impl.jdbc.EmbedConnection40.<init>(Unknown Source)
	at org.apache.derby.jdbc.Driver40.getNewEmbedConnection(Unknown Source)
	at org.apache.derby.jdbc.InternalDriver.connect(Unknown Source)
	at org.apache.derby.jdbc.Driver20.connect(Unknown Source)
	at org.apache.derby.jdbc.EmbeddedDriver.connect(Unknown Source)
	at org.apache.derby.impl.drda.Database.makeConnection(Unknown Source)
	at org.apache.derby.impl.drda.DRDAConnThread.getConnFromDatabaseName(Unknown Source)
	at org.apache.derby.impl.drda.DRDAConnThread.verifyUserIdPassword(Unknown Source)
	at org.apache.derby.impl.drda.DRDAConnThread.parseSECCHK(Unknown Source)
	at org.apache.derby.impl.drda.DRDAConnThread.parseDRDAConnection(Unknown Source)
	at org.apache.derby.impl.drda.DRDAConnThread.processCommands(Unknown Source)
	at org.apache.derby.impl.drda.DRDAConnThread.run(Unknown Source)
Caused by: java.sql.SQLException: Banco de dados 'cinemaDB' não encontrado.
	at org.apache.derby.impl.jdbc.SQLExceptionFactory.getSQLException(Unknown Source)
	at org.apache.derby.impl.jdbc.SQLExceptionFactory40.wrapArgsForTransportAcrossDRDA(Unknown Source)
	... 19 more
============= begin nested exception, level (1) ===========
java.sql.SQLException: Banco de dados 'cinemaDB' não encontrado.
	at org.apache.derby.impl.jdbc.SQLExceptionFactory.getSQLException(Unknown Source)
	at org.apache.derby.impl.jdbc.SQLExceptionFactory40.wrapArgsForTransportAcrossDRDA(Unknown Source)
	at org.apache.derby.impl.jdbc.SQLExceptionFactory40.getSQLException(Unknown Source)
	at org.apache.derby.impl.jdbc.Util.newEmbedSQLException(Unknown Source)
	at org.apache.derby.impl.jdbc.Util.newEmbedSQLException(Unknown Source)
	at org.apache.derby.impl.jdbc.Util.generateCsSQLException(Unknown Source)
	at org.apache.derby.impl.jdbc.EmbedConnection.newSQLException(Unknown Source)
	at org.apache.derby.impl.jdbc.EmbedConnection.handleDBNotFound(Unknown Source)
	at org.apache.derby.impl.jdbc.EmbedConnection.<init>(Unknown Source)
	at org.apache.derby.impl.jdbc.EmbedConnection40.<init>(Unknown Source)
	at org.apache.derby.jdbc.Driver40.getNewEmbedConnection(Unknown Source)
	at org.apache.derby.jdbc.InternalDriver.connect(Unknown Source)
	at org.apache.derby.jdbc.Driver20.connect(Unknown Source)
	at org.apache.derby.jdbc.EmbeddedDriver.connect(Unknown Source)
	at org.apache.derby.impl.drda.Database.makeConnection(Unknown Source)
	at org.apache.derby.impl.drda.DRDAConnThread.getConnFromDatabaseName(Unknown Source)
	at org.apache.derby.impl.drda.DRDAConnThread.verifyUserIdPassword(Unknown Source)
	at org.apache.derby.impl.drda.DRDAConnThread.parseSECCHK(Unknown Source)
	at org.apache.derby.impl.drda.DRDAConnThread.parseDRDAConnection(Unknown Source)
	at org.apache.derby.impl.drda.DRDAConnThread.processCommands(Unknown Source)
	at org.apache.derby.impl.drda.DRDAConnThread.run(Unknown Source)
============= end nested exception, level (1) ===========
Cleanup action completed
Wed Oct 28 18:39:27 BRST 2015 Thread[DRDAConnThread_4,5,main] (DATABASE = cinemaDB), (DRDAID = {6}), Banco de dados 'cinemaDB' não encontrado.
